<?xml version="1.0" encoding="utf-8"?>
<robot
  name="qinglongmini2.0">
  <link
    name="base_link">
    <inertial>
      <origin
        xyz="-5.73678996165089E-06 -1.69193884976709E-05 0.058874742378733"
        rpy="0 0 0" />
      <mass
        value="1.6520541" />
      <inertia
        ixx="0.0032157"
        ixy="0.0000001"
        ixz="0.0000006"
        iyy="0.0019340"
        iyz="0"
        izz="0.0028831" />
    </inertial>
    <visual>
      <origin
        xyz="0 0 0"
        rpy="0 0 0" />
      <geometry>
        <mesh
          filename="../meshes/base_link.STL" />
      </geometry>
      <material
        name="">
        <color
          rgba="0.898039215686275 0.917647058823529 0.929411764705882 1" />
      </material>
    </visual>
    <collision>
      <origin
        xyz="0 0 0"
        rpy="0 0 0" />
      <geometry>
        <mesh
          filename="../meshes/base_link.STL" />
      </geometry>
    </collision>
  </link>
  <link
    name="right_hip_pitch_link">
    <inertial>
      <origin
        xyz="0.00335760201078564 -0.0373080226674996 -0.0624910254096332"
        rpy="0 0 0" />
      <mass
        value="0.5798660" />
      <inertia
        ixx="0.0008730"
        ixy="0.0000052"
        ixz="0.0000225"
        iyy="0.0007970"
        iyz="-0.0001053"
        izz="0.0003964" />
    </inertial>
    <visual>
      <origin
        xyz="0 0 0"
        rpy="0 0 0" />
      <geometry>
        <mesh
          filename="../meshes/right_hip_pitch_link.STL" />
      </geometry>
      <material
        name="">
        <color
          rgba="0.898039215686275 0.917647058823529 0.929411764705882 1" />
      </material>
    </visual>
    <collision>
      <origin
        xyz="0 0 0"
        rpy="0 0 0" />
      <geometry>
        <mesh
          filename="../meshes/right_hip_pitch_link.STL" />
      </geometry>
    </collision>
  </link>
  <joint
    name="right_hip_pitch_joint"
    type="revolute">
    <origin
      xyz="0 -0.054017 0.059"
      rpy="0 0 0" />
    <parent
      link="base_link" />
    <child
      link="right_hip_pitch_link" />
    <axis
      xyz="0 1 0" />
    <limit
      lower="-2.2689"
      upper="2.2689"
      effort="36"
      velocity="50" />
  </joint>
  <link
    name="right_hip_roll_link">
    <inertial>
      <origin
        xyz="-0.0096013 -1.7563E-07 -0.060983"
        rpy="0 0 0" />
      <mass
        value="0.5591978" />
      <inertia
        ixx="0.0009817"
        ixy="-0.0000003"
        ixz="0.0000041"
        iyy="0.0011193"
        iyz="0"
        izz="0.0004282" />
    </inertial>
    <visual>
      <origin
        xyz="0 0 0"
        rpy="0 0 0" />
      <geometry>
        <mesh
          filename="../meshes/right_hip_roll_link.STL" />
      </geometry>
      <material
        name="">
        <color
          rgba="0.89804 0.91765 0.92941 1" />
      </material>
    </visual>
    <collision>
      <origin
        xyz="0 0 0"
        rpy="0 0 0" />
      <geometry>
        <mesh
          filename="../meshes/right_hip_roll_link.STL" />
      </geometry>
    </collision>
  </link>
  <joint
    name="right_hip_roll_joint"
    type="revolute">
    <origin
      xyz="0.00945 -0.04 -0.074"
      rpy="0 0 0" />
    <parent
      link="right_hip_pitch_link" />
    <child
      link="right_hip_roll_link" />
    <axis
      xyz="1 0 0" />
    <limit
      lower="-1.0472"
      upper="0.8727"
      effort="14"
      velocity="37.7" />
  </joint>
  <link
    name="right_hip_yaw_link">
    <inertial>
      <origin
        xyz="-4.23390510687766E-06 0.00413396977649125 -0.0521520218910281"
        rpy="0 0 0" />
      <mass
        value="0.5211244" />
      <inertia
        ixx="0.0003977"
        ixy="0"
        ixz="-0.0000003"
        iyy="0.0004599"
        iyz="0.0000075"
        izz="0.0003181" />
    </inertial>
    <visual>
      <origin
        xyz="0 0 0"
        rpy="0 0 0" />
      <geometry>
        <mesh
          filename="../meshes/right_hip_yaw_link.STL" />
      </geometry>
      <material
        name="">
        <color
          rgba="0.792156862745098 0.819607843137255 0.933333333333333 1" />
      </material>
    </visual>
    <collision>
      <origin
        xyz="0 0 0"
        rpy="0 0 0" />
      <geometry>
        <mesh
          filename="../meshes/right_hip_yaw_link.STL" />
      </geometry>
    </collision>
  </link>
  <joint
    name="right_hip_yaw_joint"
    type="revolute">
    <origin
      xyz="-0.00945 0 -0.104"
      rpy="0 0 0" />
    <parent
      link="right_hip_roll_link" />
    <child
      link="right_hip_yaw_link" />
    <axis
      xyz="0 0 1" />
    <limit
      lower="-0.8727"
      upper="0.8727"
      effort="14"
      velocity="33" />
  </joint>
  <link
    name="right_knee_link">
    <inertial>
      <origin
        xyz="7.14113041347386E-06 -0.00774899527578245 -0.163319540342136"
        rpy="0 0 0" />
      <mass
        value="0.8775823" />
      <inertia
        ixx="0.0076825"
        ixy="0"
        ixz="0.0000003"
        iyy="0.0076264"
        iyz="0.0001222"
        izz="0.0006223" />
    </inertial>
    <visual>
      <origin
        xyz="0 0 0"
        rpy="0 0 0" />
      <geometry>
        <mesh
          filename="../meshes/right_knee_link.STL" />
      </geometry>
      <material
        name="">
        <color
          rgba="0.898039215686275 0.917647058823529 0.929411764705882 1" />
      </material>
    </visual>
    <collision>
      <origin
        xyz="0 0 0"
        rpy="0 0 0" />
      <geometry>
        <mesh
          filename="../meshes/right_knee_link.STL" />
      </geometry>
    </collision>
  </link>
  <joint
    name="right_knee_joint"
    type="revolute">
    <origin
      xyz="0 0.00945 -0.056"
      rpy="0 0 0" />
    <parent
      link="right_hip_yaw_link" />
    <child
      link="right_knee_link" />
    <axis
      xyz="0 1 0" />
    <limit
      lower="-0.1745"
      upper="2.0499"
      effort="14"
      velocity="37.7" />
  </joint>
  <link
    name="right_foot">
    <inertial>
      <origin
        xyz="0.00298442847510103 -0.00986247346418476 -0.025627500432694"
        rpy="0 0 0" />
      <mass
        value="0.251342026054478" />
      <inertia
        ixx="0.000238056636333116"
        ixy="-3.15055464416158E-07"
        ixz="7.1535935138258E-06"
        iyy="0.000301413035110417"
        iyz="2.13664567537724E-06"
        izz="0.000331563693288264" />
    </inertial>
    <visual>
      <origin
        xyz="0 0 0"
        rpy="0 0 0" />
      <geometry>
        <mesh
          filename="../meshes/right_foot.STL" />
      </geometry>
      <material
        name="">
        <color
          rgba="0.898039215686275 0.917647058823529 0.929411764705882 1" />
      </material>
    </visual>
    <collision>
      <origin
        xyz="0 0 0"
        rpy="0 0 0" />
      <geometry>
        <mesh
          filename="../meshes/right_foot.STL" />
      </geometry>
    </collision>
  </link>
  <joint
    name="right_foot_pitch_joint"
    type="revolute">
    <origin
      xyz="0 0 -0.23"
      rpy="0 0 0" />
    <parent
      link="right_knee_link" />
    <child
      link="right_foot" />
    <axis
      xyz="0 1 0" />
    <limit
      lower="-1.0472"
      upper="1.0472"
      effort="14"
      velocity="37.7" />
  </joint>
  <link
    name="left_hip_pitch_link">
    <inertial>
      <origin
        xyz="0.0033576 0.037308 -0.062491"
        rpy="0 0 0" />
      <mass
        value="0.5798661" />
      <inertia
        ixx="0.0008730"
        ixy="-0.0000052"
        ixz="0.0000225"
        iyy="0.0007970"
        iyz="0.0001053"
        izz="0.0003964" />
    </inertial>
    <visual>
      <origin
        xyz="0 0 0"
        rpy="0 0 0" />
      <geometry>
        <mesh
          filename="../meshes/left_hip_pitch_link.STL" />
      </geometry>
      <material
        name="">
        <color
          rgba="0.89804 0.91765 0.92941 1" />
      </material>
    </visual>
    <collision>
      <origin
        xyz="0 0 0"
        rpy="0 0 0" />
      <geometry>
        <mesh
          filename="../meshes/left_hip_pitch_link.STL" />
      </geometry>
    </collision>
  </link>
  <joint
    name="left_hip_pitch_joint"
    type="revolute">
    <origin
      xyz="0 0.053983 0.059"
      rpy="0 0 0" />
    <parent
      link="base_link" />
    <child
      link="left_hip_pitch_link" />
    <axis
      xyz="0 1 0" />
    <limit
      lower="-2.2689"
      upper="2.2689"
      effort="36"
      velocity="50" />
  </joint>
  <link
    name="left_hip_roll_link">
    <inertial>
      <origin
        xyz="-0.00960126000015139 -1.75627821480395E-07 -0.0609829126488866"
        rpy="0 0 0" />
      <mass
        value="0.5591978" />
      <inertia
        ixx="0.0009821"
        ixy="0.0000003"
        ixz="0.0000041"
        iyy="0.0011189"
        iyz="0"
        izz="0.0004282" />
    </inertial>
    <visual>
      <origin
        xyz="0 0 0"
        rpy="0 0 0" />
      <geometry>
        <mesh
          filename="../meshes/left_hip_roll_link.STL" />
      </geometry>
      <material
        name="">
        <color
          rgba="0.898039215686275 0.917647058823529 0.929411764705882 1" />
      </material>
    </visual>
    <collision>
      <origin
        xyz="0 0 0"
        rpy="0 0 0" />
      <geometry>
        <mesh
          filename="../meshes/left_hip_roll_link.STL" />
      </geometry>
    </collision>
  </link>
  <joint
    name="left_hip_roll_joint"
    type="revolute">
    <origin
      xyz="0.00945 0.04 -0.074"
      rpy="0 0 0" />
    <parent
      link="left_hip_pitch_link" />
    <child
      link="left_hip_roll_link" />
    <axis
      xyz="1 0 0" />
    <limit
      lower="-0.8727"
      upper="1.0472"
      effort="14"
      velocity="37.7" />
  </joint>
  <link
    name="left_hip_yaw_link">
    <inertial>
      <origin
        xyz="1.8343574517167E-05 -0.00413396978427791 -0.0521438044149684"
        rpy="0 0 0" />
      <mass
        value="0.5211244" />
      <inertia
        ixx="0.0003977"
        ixy="-0.0000001"
        ixz="-0.0000002"
        iyy="0.0004599"
        iyz="-0.0000075"
        izz="0.0003181" />
    </inertial>
    <visual>
      <origin
        xyz="0 0 0"
        rpy="0 0 0" />
      <geometry>
        <mesh
          filename="../meshes/left_hip_yaw_link.STL" />
      </geometry>
      <material
        name="">
        <color
          rgba="0.898039215686275 0.917647058823529 0.929411764705882 1" />
      </material>
    </visual>
    <collision>
      <origin
        xyz="0 0 0"
        rpy="0 0 0" />
      <geometry>
        <mesh
          filename="../meshes/left_hip_yaw_link.STL" />
      </geometry>
    </collision>
  </link>
  <joint
    name="left_hip_yaw_joint"
    type="revolute">
    <origin
      xyz="-0.00945 0 -0.104"
      rpy="0 0 0" />
    <parent
      link="left_hip_roll_link" />
    <child
      link="left_hip_yaw_link" />
    <axis
      xyz="0 0 1" />
    <limit
      lower="-0.8727"
      upper="0.8727"
      effort="14"
      velocity="33" />
  </joint>
  <link
    name="left_knee_link">
    <inertial>
      <origin
        xyz="6.3236898386887E-06 0.0077489947037703 -0.163324325687469"
        rpy="0 0 0" />
      <mass
        value="0.8775823" />
      <inertia
        ixx="0.0076825"
        ixy="0"
        ixz="0.0000003"
        iyy="0.0076264"
        iyz="-0.0001222"
        izz="0.0006223" />
    </inertial>
    <visual>
      <origin
        xyz="0 0 0"
        rpy="0 0 0" />
      <geometry>
        <mesh
          filename="../meshes/left_knee_link.STL" />
      </geometry>
      <material
        name="">
        <color
          rgba="0.898039215686275 0.917647058823529 0.929411764705882 1" />
      </material>
    </visual>
    <collision>
      <origin
        xyz="0 0 0"
        rpy="0 0 0" />
      <geometry>
        <mesh
          filename="../meshes/left_knee_link.STL" />
      </geometry>
    </collision>
  </link>
  <joint
    name="left_knee_joint"
    type="revolute">
    <origin
      xyz="0 -0.00945 -0.056"
      rpy="0 0 0" />
    <parent
      link="left_hip_yaw_link" />
    <child
      link="left_knee_link" />
    <axis
      xyz="0 1 0" />
    <limit
      lower="-0.1745"
      upper="2.0944"
      effort="14"
      velocity="37.7" />
  </joint>
  <link
    name="left_foot">
    <inertial>
      <origin
        xyz="0.00298442754260854 0.00986282632621122 -0.0256275009097112"
        rpy="0 0 0" />
      <mass
        value="0.251342032302528" />
      <inertia
        ixx="0.000238056567309221"
        ixy="3.14440711603497E-07"
        ixz="7.15358983941389E-06"
        iyy="0.000301413041828796"
        iyz="-2.13704063447588E-06"
        izz="0.000331563627961346" />
    </inertial>
    <visual>
      <origin
        xyz="0 0 0"
        rpy="0 0 0" />
      <geometry>
        <mesh
          filename="../meshes/left_foot.STL" />
      </geometry>
      <material
        name="">
        <color
          rgba="0.898039215686275 0.917647058823529 0.929411764705882 1" />
      </material>
    </visual>
    <collision>
      <origin
        xyz="0 0 0"
        rpy="0 0 0" />
      <geometry>
        <mesh
          filename="../meshes/left_foot.STL" />
      </geometry>
    </collision>
  </link>
  <joint
    name="left_foot_pitch_link"
    type="revolute">
    <origin
      xyz="0 0 -0.23"
      rpy="0 0 0" />
    <parent
      link="left_knee_link" />
    <child
      link="left_foot" />
    <axis
      xyz="0 1 0" />
    <limit
      lower="-1.0472"
      upper="1.0472"
      effort="14"
      velocity="33" />
  </joint>
  <link
    name="waist_yaw_link">
    <inertial>
      <origin
        xyz="-0.00048399 -0.0020022 0.10215"
        rpy="0 0 0" />
      <mass
        value="3.6534181" />
      <inertia
        ixx="0.0221606"
        ixy="-0.0000065"
        ixz="0.0000828"
        iyy="0.0164459"
        iyz="-0.0000070"
        izz="0.0116163" />
    </inertial>
    <visual>
      <origin
        xyz="0 0 0"
        rpy="0 0 0" />
      <geometry>
        <mesh
          filename="../meshes/waist_yaw_link.STL" />
      </geometry>
      <material
        name="">
        <color
          rgba="0.79216 0.81961 0.93333 1" />
      </material>
    </visual>
    <collision>
      <origin
        xyz="0 0 0"
        rpy="0 0 0" />
      <geometry>
        <mesh
          filename="../meshes/waist_yaw_link.STL" />
      </geometry>
    </collision>
  </link>
  <joint
    name="waist_yaw_joint"
    type="revolute">
    <origin
      xyz="-1.32618415521965E-05 -1.74530893953325E-05 0.140558242606161"
      rpy="0 0 0" />
    <parent
      link="base_link" />
    <child
      link="waist_yaw_link" />
    <axis
      xyz="0 0 1" />
    <limit
      lower="-0.8727"
      upper="0.8727"
      effort="14"
      velocity="37.7" />
  </joint>
  <link
    name="right_shoulder_pitch_link">
    <inertial>
      <origin
        xyz="-0.00210427996058867 -0.0585656923115873 -1.85446469039285E-05"
        rpy="0 0 0" />
      <mass
        value="0.2947553" />
      <inertia
        ixx="0.0001067"
        ixy="-0.0000013"
        ixz="0.0000001"
        iyy="0.0001035"
        iyz="0.0000001"
        izz="0.0001283" />
    </inertial>
    <visual>
      <origin
        xyz="0 0 0"
        rpy="0 0 0" />
      <geometry>
        <mesh
          filename="../meshes/right_shoulder_pitch_link.STL" />
      </geometry>
      <material
        name="">
        <color
          rgba="0.898039215686275 0.917647058823529 0.929411764705882 1" />
      </material>
    </visual>
    <collision>
      <origin
        xyz="0 0 0"
        rpy="0 0 0" />
      <geometry>
        <mesh
          filename="../meshes/right_shoulder_pitch_link.STL" />
      </geometry>
    </collision>
  </link>
  <joint
    name="right_shoulder_pitch_joint"
    type="revolute">
    <origin
      xyz="1.3262E-05 -0.0881 0.17234"
      rpy="0 0 0" />
    <parent
      link="waist_yaw_link" />
    <child
      link="right_shoulder_pitch_link" />
    <axis
      xyz="0 1 0" />
    <limit
      lower="-2.7925"
      upper="2.7925"
      effort="14"
      velocity="33" />
  </joint>
  <link
    name="right_shoulder_roll_link">
    <inertial>
      <origin
        xyz="0.0041115542372811 0.000365350255664781 -0.0578635363052412"
        rpy="0 0 0" />
      <mass
        value="0.3485680" />
      <inertia
        ixx="0.0003275"
        ixy="0"
        ixz="0.0000080"
        iyy="0.0003715"
        iyz="-0.0000001"
        izz="0.0001563" />
    </inertial>
    <visual>
      <origin
        xyz="0 0 0"
        rpy="0 0 0" />
      <geometry>
        <mesh
          filename="../meshes/right_shoulder_roll_link.STL" />
      </geometry>
      <material
        name="">
        <color
          rgba="0.898039215686275 0.917647058823529 0.929411764705882 1" />
      </material>
    </visual>
    <collision>
      <origin
        xyz="0 0 0"
        rpy="0 0 0" />
      <geometry>
        <mesh
          filename="../meshes/right_shoulder_roll_link.STL" />
      </geometry>
    </collision>
  </link>
  <joint
    name="right_shoulder_roll_joint"
    type="revolute">
    <origin
      xyz="-0.0044996 -0.062176 -0.00015572"
      rpy="0 0 0" />
    <parent
      link="right_shoulder_pitch_link" />
    <child
      link="right_shoulder_roll_link" />
    <axis
      xyz="1 0 0" />
    <limit
      lower="-3.2289"
      upper="0.0873"
      effort="6"
      velocity="45" />
  </joint>
  <link
    name="right_shoulder_yaw_link">
    <inertial>
      <origin
        xyz="-8.56685334881674E-06 -0.00187746646855333 -0.0317422855661479"
        rpy="0 0 0" />
      <mass
        value="0.2995524" />
      <inertia
        ixx="0.0001315"
        ixy="0"
        ixz="-0.0000001"
        iyy="0.0001081"
        iyz="-0.0000019"
        izz="0.0001062" />
    </inertial>
    <visual>
      <origin
        xyz="0 0 0"
        rpy="0 0 0" />
      <geometry>
        <mesh
          filename="../meshes/right_shoulder_yaw_link.STL" />
      </geometry>
      <material
        name="">
        <color
          rgba="0.898039215686275 0.917647058823529 0.929411764705882 1" />
      </material>
    </visual>
    <collision>
      <origin
        xyz="0 0 0"
        rpy="0 0 0" />
      <geometry>
        <mesh
          filename="../meshes/right_shoulder_yaw_link.STL" />
      </geometry>
    </collision>
  </link>
  <joint
    name="right_shoulder_yaw_joint"
    type="revolute">
    <origin
      xyz="0.0044996 0.00026128 -0.094639"
      rpy="0 0 0" />
    <parent
      link="right_shoulder_roll_link" />
    <child
      link="right_shoulder_yaw_link" />
    <axis
      xyz="0 0 1" />
    <limit
      lower="-2.9671"
      upper="2.9671"
      effort="6"
      velocity="45" />
  </joint>
  <link
    name="right_elbow_link">
    <inertial>
      <origin
        xyz="0.0786473480273473 0.00380297012793684 -0.000353678677222103"
        rpy="0 0 0" />
      <mass
        value="0.1977884" />
      <inertia
        ixx="0.0000909"
        ixy="-0.0000109"
        ixz="0.0000004"
        iyy="0.0008559"
        iyz="0.0000001"
        izz="0.0009024" />
    </inertial>
    <visual>
      <origin
        xyz="0 0 0"
        rpy="0 0 0" />
      <geometry>
        <mesh
          filename="../meshes/right_elbow_link.STL" />
      </geometry>
      <material
        name="">
        <color
          rgba="0.898039215686275 0.917647058823529 0.929411764705882 1" />
      </material>
    </visual>
    <collision>
      <origin
        xyz="0 0 0"
        rpy="0 0 0" />
      <geometry>
        <mesh
          filename="../meshes/right_elbow_link.STL" />
      </geometry>
    </collision>
  </link>
  <joint
    name="right_elbow_joint"
    type="revolute">
    <origin
      xyz="-0.00015572 -0.0043849 -0.034624"
      rpy="0 0 0" />
    <parent
      link="right_shoulder_yaw_link" />
    <child
      link="right_elbow_link" />
    <axis
      xyz="0 1 0" />
    <limit
      lower="-0.1745"
      upper="1.9199"
      effort="6"
      velocity="45" />
  </joint>
  <link
    name="left_shoulder_pitch_link">
    <inertial>
      <origin
        xyz="-0.00210428325739485 0.0585226139172226 -7.07840754010647E-07"
        rpy="0 0 0" />
      <mass
        value="0.2947554" />
      <inertia
        ixx="0.0001066"
        ixy="0.0000015"
        ixz="0"
        iyy="0.0001035"
        iyz="-0.0000001"
        izz="0.0001282" />
    </inertial>
    <visual>
      <origin
        xyz="0 0 0"
        rpy="0 0 0" />
      <geometry>
        <mesh
          filename="../meshes/left_shoulder_pitch_link.STL" />
      </geometry>
      <material
        name="">
        <color
          rgba="0.792156862745098 0.819607843137255 0.933333333333333 1" />
      </material>
    </visual>
    <collision>
      <origin
        xyz="0 0 0"
        rpy="0 0 0" />
      <geometry>
        <mesh
          filename="../meshes/left_shoulder_pitch_link.STL" />
      </geometry>
    </collision>
  </link>
  <joint
    name="left_shoulder_pitch_joint"
    type="revolute">
    <origin
      xyz="1.3262E-05 0.0881 0.17234"
      rpy="0 0 0" />
    <parent
      link="waist_yaw_link" />
    <child
      link="left_shoulder_pitch_link" />
    <axis
      xyz="0 1 0" />
    <limit
      lower="-2.7925"
      upper="2.7925"
      effort="14"
      velocity="33" />
  </joint>
  <link
    name="left_shoulder_roll_link">
    <inertial>
      <origin
        xyz="0.00412098513032669 0.000363759745852399 -0.0581749827430238"
        rpy="0 0 0" />
      <mass
        value="0.3485680" />
      <inertia
        ixx="0.0003276"
        ixy="-0.0000001"
        ixz="0.0000080"
        iyy="0.0003714"
        iyz="0.0000001"
        izz="0.0001563" />
    </inertial>
    <visual>
      <origin
        xyz="0 0 0"
        rpy="0 0 0" />
      <geometry>
        <mesh
          filename="../meshes/left_shoulder_roll_link.STL" />
      </geometry>
      <material
        name="">
        <color
          rgba="0.898039215686275 0.917647058823529 0.929411764705882 1" />
      </material>
    </visual>
    <collision>
      <origin
        xyz="0 0 0"
        rpy="0 0 0" />
      <geometry>
        <mesh
          filename="../meshes/left_shoulder_roll_link.STL" />
      </geometry>
    </collision>
  </link>
  <joint
    name="left_shoulder_roll_joint"
    type="revolute">
    <origin
      xyz="-0.0044996 0.061424 0.00015572"
      rpy="0 0 0" />
    <parent
      link="left_shoulder_pitch_link" />
    <child
      link="left_shoulder_roll_link" />
    <axis
      xyz="1 0 0" />
    <limit
      lower="-0.0873"
      upper="3.2289"
      effort="6"
      velocity="45" />
  </joint>
  <link
    name="left_shoulder_yaw_link">
    <inertial>
      <origin
        xyz="1.99648881145653E-05 0.00187745723766075 -0.0317708173076113"
        rpy="0 0 0" />
      <mass
        value="0.2995524" />
      <inertia
        ixx="0.0001317"
        ixy="0.0000001"
        ixz="-0.0000001"
        iyy="0.0001081"
        iyz="0.0000018"
        izz="0.0001061" />
    </inertial>
    <visual>
      <origin
        xyz="0 0 0"
        rpy="0 0 0" />
      <geometry>
        <mesh
          filename="../meshes/left_shoulder_yaw_link.STL" />
      </geometry>
      <material
        name="">
        <color
          rgba="0.898039215686275 0.917647058823529 0.929411764705882 1" />
      </material>
    </visual>
    <collision>
      <origin
        xyz="0 0 0"
        rpy="0 0 0" />
      <geometry>
        <mesh
          filename="../meshes/left_shoulder_yaw_link.STL" />
      </geometry>
    </collision>
  </link>
  <joint
    name="left_shoulder_yaw_joint"
    type="revolute">
    <origin
      xyz="0.0044996 0.00049061 -0.09495"
      rpy="0 0 0" />
    <parent
      link="left_shoulder_roll_link" />
    <child
      link="left_shoulder_yaw_link" />
    <axis
      xyz="0 0 1" />
    <limit
      lower="-2.9671"
      upper="2.9671"
      effort="6"
      velocity="45" />
  </joint>
  <link
    name="left_elbow_link">
    <inertial>
      <origin
        xyz="0.0781156956631344 -0.00380297588342884 0.000177982252860054"
        rpy="0 0 0" />
      <mass
        value="0.1977884" />
      <inertia
        ixx="0.0000909"
        ixy="0.0000109"
        ixz="0.0000004"
        iyy="0.0008559"
        iyz="-0.0000001"
        izz="0.0009024" />
    </inertial>
    <visual>
      <origin
        xyz="0 0 0"
        rpy="0 0 0" />
      <geometry>
        <mesh
          filename="../meshes/left_elbow_link.STL" />
      </geometry>
      <material
        name="">
        <color
          rgba="0.898039215686275 0.917647058823529 0.929411764705882 1" />
      </material>
    </visual>
    <collision>
      <origin
        xyz="0 0 0"
        rpy="0 0 0" />
      <geometry>
        <mesh
          filename="../meshes/left_elbow_link.STL" />
      </geometry>
    </collision>
  </link>
  <joint
    name="left_elbow_joint"
    type="revolute">
    <origin
      xyz="0.00037594 0.0043849 -0.035156"
      rpy="0 0 0" />
    <parent
      link="left_shoulder_yaw_link" />
    <child
      link="left_elbow_link" />
    <axis
      xyz="0 1 0" />
    <limit
      lower="-0.1745"
      upper="1.9199"
      effort="6"
      velocity="45" />
  </joint>
</robot>